

>[!note] 예외란? 
>일반적이지 않은 상황, 즉 프로그램이 실행되는 동안에 발생하는 예기치 않은 에러
>프로그래머들이 예상하지 못한 상황에 대해서 어떻게 대처할지에 대해서 프로그램 해야함

>[!note] Java Compile 방식
>Java는 위에서 아래로 읽는데 오류가 발생하면 해당 위치에서 더이상 컴파일 하지 않는다.


>[!tip] try () catch()
> try ( 정상적일때 실행상황) catch(비정상일때 실행상황)


>[!tip] Multi Thread
>1. 멀티스레드란 하나의 프로그램내에서 여러 개의 작은 작업이 동시에 수행되는 것
>2. 멀티스레드 구현 방법
>	가. Therad 클래스 상속받는법
>	- Thread 클래스를 상속받아 멀티스레드를 구현하면 방법은 쉽지만, 단일 상속만 가능하다는 단점이 있다.
>	나. Runnable 인터페이스를 상속받는법
>	- 다중 상속을 받을 수 있다는 장점이 있다. 하지만 멀티스레드를 시작하는 start() 메소드가 없기 때문에 인터페이스를 상속받은 자식클래스 객체를 Thread 클래스 생성자 인자값으로 넘겨줘서 다시 한번더 객체를 생성해서 start() 메소드를 호출해야 한다는 단점이 있다.
>1. 멀티스레드에서 start() 메소드를 호출하면 멀티스레드가 시작되면서 run() 메서드를 자동 호출한다. 명시적인 run()메소드를 호출하지 않아도 start() 메소드만 호출하면 바로 자동 호출되는 run()메소드 내에 멀티스레드 문장을 구현한다.


### TryCatch

>[!note] try{} catch() {} 구문이란?
>정상적일 때 상황과 에러가 발생했을 때 상황을 구분함으로써 System Error발생으로 인한 Pro 멈춤을 예방

```java title=TryCatch01
package Exception;

// 가장 일반적인 예외처리 코드
// try{
// 	정상구문이 실행되다가 예외가 발생하면 아래문장을 더이상 실행하지 않고 제어 순서가 해장 catch블록문{}으로 옮겨진다
// } catch(예외처리 클래스 매개변수) {
// 	예외 처리코드;
// }

// 자바코드에서 가장 일반적인 예외 발생코드는 정수 숫자를 0으로 나눌 때 AirthmeticException 예외 오류가 발생한다.

public class TryCatch01 {
	public static void main(String[] args) {
		int a = 10, b01 = 0, b02 = 2, result = 0;
		
		try {
			result = a/b02;
			System.out.println(result);
			
			result = a/b01;
			// 예외가 발생해서 아래 문장 실행하지 않고 제어순서가 해당 catch{}블록문으로 옮겨진다.
			// 예외발생 => 정수 숫자를 0으로 나누면서 발생함.
			System.out.println(result);
			// 이 문장 실행 안함
			
		} catch(Exception e) {
			System.out.println("예외가 발생하면 Exception 예외처리 클래스가 잡음 => " + e);
		}
	}
}

```

>[!note] Run
>5
>예외가 발생하면 Exception 예외처리 클래스가 잡음 => java.lang.ArithmeticException: / by zero

>[!tip] 에러가 발생한 이유
>정수 숫자를 '0'으로 나눔으로 인해 Error가 발생(ArithmeticExceoption)


---

```java title=TryCatch02
package Exception;

// 복수개의 catch블록문{}을 사용하면 예외처리 자손클래스가 먼저 나오고 부모클래스는 나중에 나와야 한다.

public class TryCatch02 {
	public static void main(String[] args) {
		int a = 10, b01 = 0, b02 = 2, result = 0;
		
		try {
			result = a/b02;
			System.out.println(result);
			
			result = a/b01;
			// 예외가 발생
			System.out.println(result);
		} catch (ArithmeticException ae) {
			// Exception 보더 먼저 나와야함
			ae.printStackTrace(); // 예외 족적을 남김
		} catch(Exception e) {
			e.printStackTrace();
		}
	}
}

```

>[!note] Run
>5
java.lang.ArithmeticException: / by zero at Exception.TryCatch02.main(TryCatch02.java:13)

>[!tip] 에러가 발생한 이유
>정수 숫자를 '0'으로 나눔으로 인해 Error가 발생(ArithmeticException)

---

### finally{}

>[!note] finally{} 구문이란?
>try{} 구문내에서 정상구문이 실행이 되는 예외가 발생하든지에 상관없이 무조건 마지막에 실행문장을 수행처리 하기 위함

```java title=TryCatch03
package Exception;

// try{} 구문내에서 정상구문이 실행이 되는 예외가 발생하든지에 상관없이 무조건 마지막에 실행문장을 수행처리 하기위해서는 finally{}블록문을 사용해야 한다.

public class TryCatch03 {
	public static void main(String[] args) {
		int a = 10, b01 = 0, b02 = 2, result = 0;
		
		try {
			result = a/b02;
			System.out.println(result);
			
			result = a/b01; // 예외 발생
			System.out.println(result); // 이문장 수행안함.
			
		} catch(ArithmeticException ae) {
			ae.printStackTrace();
		} catch(Exception e) {
			System.out.println("예외 발생 : " + e);
		} finally {
			System.out.println("예외 발생 유무와 상관없이 마지막에 실행");
		}
	}
}

```

>[!note] Run
>5
java.lang.ArithmeticException: / by zero at Exception.TryCatch03.main(TryCatch03.java:13)
예외 발생 유무와 상관없이 마지막에 실행

>[!tip] 에러가 발생한 이유
>정수 숫자를 '0'으로 나눔으로 인해 Error가 발생(ArithmeticException)

---

### NullPointerException

```java title=TryCatch04
package Exception;

// NullPointException 예외 처리클래스 실습

class Member {
	String id = "abc56789";
	String name = "홍길동";
	String email = "hong5678@gmail.com";
}

public class TryCatch04 {
	public static void main(String[] args) {
		
		Member m = null;
		// 객체변수 참조하지 않고 null값 대입
		try {
			System.out.println("아이디 =" + m.id + ", 회원이름 =" + m.name + ", 이메일 = " + m.email);
			// 현재 m의 속성에 대한 값이 null로 표기되어 NullPointException Error가 발생함
		} catch(Exception e) {
			System.out.println("예외발생:"+e);
			m = new Member();
			System.out.println("아이디 =" + m.id + ", 회원이름 =" + m.name + ", 이메일 = " + m.email);
		}
		
	}
}

```

>[!note] Run
>예외발생:java.lang.NullPointerException: Cannot read field "id" because "m" is null
>아이디 =abc56789, 회원이름 =홍길동, 이메일 = hong5678@gmail.com

>[!tip] 에러가 발생한 이유
>참조변수 값이 null이므로 m.id(null값)을 표기할 수 없음으로 에러(NullPointerException)

---

### ArrayIndexOutOfBoundsException

``` java title=TryCatch05
package Exception;

// ArrayIndexOutOfBoundsException 예외 처리 클래스는 배열 주소범위를 벗어났을 경우 발생한다.

public class TryCatch05 {
	public static void main(String[] args) {
		
		int numArr[] = {10, 20, 30};
		
		try {
			System.out.println("Test - 1");
			numArr[4] = 5; // 배열주소 범위를 벗어나서 예외 발생
			System.out.println("Test - 2"); // 이 문장 수행 안함
		} catch(Exception e) {
			System.out.println("예외 발생 :" + e );
		} finally {
			System.out.println("Test - 3");
		}
	}
}

```

>[!note] Run
>Test - 1
예외 발생 :java.lang.ArrayIndexOutOfBoundsException: Index 4 out of bounds for length 3
Test - 3

>[!tip] 에러가 발생한 이유
>배열의 주소는 [0, 1, 2] 까지 인데 [4]주소를 호출했으므로 에러 발생(ArrayIndexOutOfBoundsException)

---

### throw

```java title=TryCatch06
package Exception;

// 1. throw 에 의한 인위적 예외 발생
// 2. throws 에 의한 메소드를 호출한 곳으로 예외를 넘기는 경우

public class TryCatch06 {
	
	public static void exp(int data) throws NullPointerException {
		// 정적 메소드 생성 (throws NullPointerException : NullPointerExceiption Error 가 발생할 가능성이 있다)
		if(data == 0)
			throw new NullPointerException(); // 인위적 예외 발생
	}
	
	public static void main(String[] args) {
		try {
			System.out.println("예외 발생하는 메소드 호출 전");
			exp(0); // exp 메소드 호출하면서 예외가 발생
			System.out.println("예외 발생하는 메소드 호출 후"); // 이 문장 수행 안함
		} catch(NullPointerException ne) {
			System.out.println("예외 발생 :" + ne);
		}
	}
}

```

>[!note] Run
>예외 발생하는 메소드 호출 전
예외 발생 :java.lang.NullPointerException

>[!tip] exp메소드에 throws NullPointerExceoption이 작성된 이유
>(throws NullPointerException : NullPointerExceiption Error 가 발생할 가능성이 있다)
>현재 코드는 강제적으로 0의 매개변수를 받음으로써 에러가 발생한다.

---

### 사용자 정의 예외 클래스 생성
```java title=TryCatch07
package Exception;

// 사용자 정의 예외 클래스 생성 예제

class UserException extends Exception{
	public UserException(String errMsg) {
		super(errMsg); // 부모클래스(Exception) 오버로딩 된 생성자 호출
	}
}

public class TryCatch07 {
	public static void main(String[] args) {
		try {
			int data = -10;
			if(data <= 0) {
				throw new UserException("양수가 아닙니다");
			}
		} catch(UserException ue) {
			System.out.println(ue.getMessage()); // 예외 에러 메시지 출력
		}
	}
}

```

>[!note] Run
>양수가 아닙니다

---

### AutoCloseable

```java title=TryCatch08
package Exception;

import java.io.PrintWriter;
import java.util.ArrayList;
import java.util.List;

//자바7에서 추가된 AutoColseable 인터페이스를 구현상속받은 자손은 try()내에서 객체를 생성하면 finally 블록문에서 명시적 코드로 close() 하지 않아도 자동으로 닫힌다

public class TryCatch08 {
	public static void main(String[] args) throws Exception{
		
		List<String> cityList = new ArrayList<>();
		cityList.add("seoul");
		cityList.add("busan");
		cityList.add("suwon");
		
		try(PrintWriter output = new PrintWriter("./src/Exception/result.txt")) {
			// PrintWriter api는 문자출력스트림
			// PrintWriter 는 이미 예외처리가능성이 있으므로 메소드에서 thorws Exception을 해야한다.
			
			for(String cityName:cityList) {
				// cityList배열에 있는 값들 하나씩 cityName에 넣고 for을 반복동작한다
				output.println(cityName.toUpperCase());
				// 영문 대문자로 변경해서 result.txt에 기록
			}
		} 
	}
}

```

>[!note] Run
>./src/Exception/ 경로에 result.txt 파일을 생성하여 cityList 배열의 값들을 기록한다.

>[!tip] PrintWriter API
>Java를 통해 외부 폴더에 텍스트파일을 만들어 기록할 수 있다.

---

### Math.random()
```java title=TryCatch09
package Exception;

// Math.random()을 사용해서 0부터 9사이의 임의의 정수숫자 난수를 발생한 다음 해당 난수로 100정수 숫자를 나눗셈 했을 때 발생하는 예외처리

public class TryCatch09 {
	public static void main(String[] args) {
		
		int number = 100;
		int result = 0;
		
		for(int i=0; i<10; i++) {
			try {
				result = number/(int)(Math.random()*10);
				// Math.random() 메소드는 0.0이상 1.0미만 사이의 실수숫자 난수를 발생
				// number(100) / (int값 형변환)(double 0.0~1.0) * 10 진행
				System.out.println(result);
			} catch(ArithmeticException ae) {
				System.out.println("발생한 임의의 정수난수 숫자 = 0" );
				
			}
		}
	}
}

```

>[!note] Run
>100
14
20
100
발생한 임의의 정수난수 숫자 = 0
16
33
발생한 임의의 정수난수 숫자 = 0
25
발생한 임의의 정수난수 숫자 = 0
>항상 값이 다르게나옴(난수)

>[!tip] 에러가 발생할 경우
>Math.random에서 0.0값이 나왔을때 에러가 발생(ArithmeticException)


---


